<?xml version="1.0" encoding="utf-8"?>
<robot name="f5d6_right">
  <link name="R_wrist" />
  <joint name="R_wirst_joint" type="fixed">
    <origin xyz="-0.00385 0 0" rpy="0 1.57079 3.14159" />
    <parent link="R_wrist" />
    <child link="R_hand_base" />
  </joint>
  <link name="R_hand_base">
    <inertial>
      <origin xyz="-0.04133 -0.00272 -0.00667" rpy="0 0 0" />
      <mass value="0.03659" />
      <inertia ixx="1.14586E-05" ixy="-1.17421E-06" ixz="8.02063E-07"
        iyy="9.13975E-06" iyz="-2.84474E-07" izz="1.41942E-05" />
    </inertial>
    <visual>
      <origin xyz="0 0 0" rpy="0 0 0" />
      <geometry>
        <mesh filename="meshes/visual/R_hand_base.glb" />
      </geometry>
    </visual>
    <collision>
      <origin xyz="-0.011 0 -0.00375" rpy="0 1.57059 0" />
      <geometry>
        <cylinder radius="0.0245" length="0.022" />
      </geometry>
    </collision>
    <collision>
      <origin xyz="0 0 0" rpy="0 0 0" />
      <geometry>
        <mesh filename="meshes/collision/R_hand_base.obj" />
      </geometry>
    </collision>
  </link>
  <link name="R_th_l0">
    <inertial>
      <origin xyz="0.00118 -0.00613 -0.00213" rpy="0 0 0" />
      <mass value="0.00232" />
      <inertia ixx="1.75838E-07" ixy="-5.95375E-08" ixz="-5.14845E-09"
        iyy="1.47472E-07" iyz="-1.16870E-08" izz="1.75668E-07" />
    </inertial>
    <visual>
      <origin xyz="0 0 0" rpy="0 0 0" />
      <geometry>
        <mesh filename="meshes/visual/th_l0.glb" />
      </geometry>
    </visual>
    <collision>
      <origin xyz="0 0 0" rpy="0 0 0" />
      <geometry>
        <mesh filename="meshes/collision/th_l0.obj" />
      </geometry>
    </collision>
  </link>
  <joint name="R_th_j0" type="revolute">
    <origin xyz="-0.04608 -0.01984 -0.02687" rpy="-0.00287 -0.21841 0.01325" />
    <parent link="R_hand_base" />
    <child link="R_th_l0" />
    <axis xyz="1 0 0" />
    <limit lower="-0.0158" upper="1.605" effort="1.0" velocity="6.28" />
  </joint>
  <link name="R_th_l1">
    <inertial>
      <origin xyz="0.01732 -0.00805 -0.00337" rpy="0 0 0" />
      <mass value="0.00416" />
      <inertia ixx="2.66072E-07" ixy="2.70383E-07" ixz="-2.29989E-08"
        iyy="1.00883E-06" iyz="1.70663E-08" izz="1.17421E-06" />
    </inertial>
    <visual>
      <origin xyz="0 0 0" rpy="0 0 0" />
      <geometry>
        <mesh filename="meshes/visual/th_l1.glb" />
      </geometry>
    </visual>
    <collision>
      <origin xyz="0 0 0" rpy="0 0 0" />
      <geometry>
        <mesh filename="meshes/collision/th_l1.obj" />
      </geometry>
    </collision>
  </link>
  <joint name="R_th_j1" type="revolute">
    <origin xyz="-0.00675 -0.02097 -0.00276" rpy="3.13870 -0.00004 3.12870" />
    <parent link="R_th_l0" />
    <child link="R_th_l1" />
    <axis xyz="0 0 -1" />
    <limit lower="-0.3468" upper="0.1834" effort="1.0" velocity="6.28" />
  </joint>
  <link name="R_th_l2">
    <inertial>
      <origin xyz="0.00825 -0.00781 -0.00190" rpy="0 0 0" />
      <mass value="0.00503" />
      <inertia ixx="1.99369E-07" ixy="5.81238E-08" ixz="-6.38608E-12"
        iyy="2.67971E-07" iyz="-8.07033E-13" izz="2.35242E-07" />
    </inertial>
    <visual>
      <origin xyz="0 0 0" rpy="0 0 0" />
      <geometry>
        <mesh filename="meshes/visual/th_l2.glb" />
      </geometry>
    </visual>
    <collision>
      <origin xyz="0 0 0" rpy="0 0 0" />
      <geometry>
        <mesh filename="meshes/collision/th_l2.obj" />
      </geometry>
    </collision>
  </link>
  <joint name="R_th_j2" type="revolute">
    <origin xyz="0.05088 -0.01301 0.00202" rpy="0 0 0" />
    <parent link="R_th_l1" />
    <child link="R_th_l2" />
    <axis xyz="0 0 -1" />
    <limit lower="-0.4298" upper="0.2731" effort="0.5" velocity="6.28" />
    <mimic joint="R_th_j1" multiplier="1.35316" offset="0.00765" />
  </joint>
  <link name="R_ff_l1">
    <inertial>
      <origin xyz="-0.01602 0.00010 -0.00754" rpy="0 0 0" />
      <mass value="0.00155" />
      <inertia ixx="6.86667E-08" ixy="-5.82417E-12" ixz="-2.71301E-08"
        iyy="1.54849E-07" iyz="7.16927E-13" izz="1.62393E-07" />
    </inertial>
    <visual>
      <origin xyz="0 0 0" rpy="0 0 0" />
      <geometry>
        <mesh filename="meshes/visual/ff_l1.glb" />
      </geometry>
    </visual>
    <collision>
      <origin xyz="0 0 0" rpy="0 0 0" />
      <geometry>
        <mesh filename="meshes/collision/ff_l1.obj" />
      </geometry>
    </collision>
  </link>
  <joint name="R_ff_j1" type="revolute">
    <origin xyz="-0.11269 -0.03066 -0.00119" rpy="0.08731 -0.00723 0.08240" />
    <parent link="R_hand_base" />
    <child link="R_ff_l1" />
    <axis xyz="0 1 0" />
    <limit lower="-1.0946" upper="0.2891" effort="0.5" velocity="6.28" />
  </joint>
  <link name="R_ff_l2">
    <inertial>
      <origin xyz="-0.01405 0.00009 -0.01877" rpy="0 0 0" />
      <mass value="0.00416" />
      <inertia ixx="3.83689E-07" ixy="3.50584E-13" ixz="-2.50617E-07"
        iyy="5.74504E-07" iyz="3.75938E-12" izz="2.66541E-07" />
    </inertial>
    <visual>
      <origin xyz="0 0 0" rpy="0 0 0" />
      <geometry>
        <mesh filename="meshes/visual/ff_l2.glb" />
      </geometry>
    </visual>
    <collision>
      <origin xyz="0 0 0" rpy="0 0 0" />
      <geometry>
        <mesh filename="meshes/collision/ff_l2.obj" />
      </geometry>
    </collision>
  </link>
  <joint name="R_ff_j2" type="revolute">
    <origin xyz="-0.03406 0 -0.01141" rpy="-0.00003 0 0.00010" />
    <parent link="R_ff_l1" />
    <child link="R_ff_l2" />
    <axis xyz="0 1 0" />
    <limit lower="-1.2101" upper="0.3681" effort="0.5" velocity="6.28" />
    <mimic joint="R_ff_j1" multiplier="1.13028" offset="-0.00053" />
  </joint>
  <link name="R_mf_l1">
    <inertial>
      <origin xyz="-0.01788 -0.00010 -0.00978" rpy="0 0 0" />
      <mass value="0.00190" />
      <inertia ixx="9.59615E-08" ixy="1.38745E-12" ixz="-5.32051E-08"
        iyy="2.34143E-07" iyz="2.76724E-12" izz="2.28131E-07" />
    </inertial>
    <visual>
      <origin xyz="0 0 0" rpy="0 0 0" />
      <geometry>
        <mesh filename="meshes/visual/mf_l1.glb" />
      </geometry>
    </visual>
    <collision>
      <origin xyz="0 0 0" rpy="0 0 0" />
      <geometry>
        <mesh filename="meshes/collision/mf_l1.obj" />
      </geometry>
    </collision>
  </link>
  <joint name="R_mf_j1" type="revolute">
    <origin xyz="-0.11597 -0.01047 0.00312" rpy="0 0 0.01325" />
    <parent link="R_hand_base" />
    <child link="R_mf_l1" />
    <axis xyz="0 1 0" />
    <limit lower="-1.0844" upper="0.2801" effort="0.5" velocity="6.28" />
  </joint>
  <link name="R_mf_l2">
    <inertial>
      <origin xyz="-0.01427 -0.00009 -0.01861" rpy="0 0 0" />
      <mass value="0.00416" />
      <inertia ixx="3.77923E-07" ixy="1.47250E-12" ixz="-2.51884E-07"
        iyy="5.74486E-07" iyz="5.20497E-12" izz="2.72289E-07" />
    </inertial>
    <visual>
      <origin xyz="0 0 0" rpy="0 0 0" />
      <geometry>
        <mesh filename="meshes/visual/mf_l2.glb" />
      </geometry>
    </visual>
    <collision>
      <origin xyz="0 0 0" rpy="0 0 0" />
      <geometry>
        <mesh filename="meshes/collision/mf_l2.obj" />
      </geometry>
    </collision>
  </link>
  <joint name="R_mf_j2" type="revolute">
    <origin xyz="-0.03829 0 -0.01467" rpy="0 0 0" />
    <parent link="R_mf_l1" />
    <child link="R_mf_l2" />
    <axis xyz="0 1 0" />
    <limit lower="-1.2026" upper="0.3533" effort="0.5" velocity="6.28" />
    <mimic joint="R_mf_j1" multiplier="1.13311" offset="-0.00079" />
  </joint>
  <link name="R_rf_l1">
    <inertial>
      <origin xyz="-0.01575 0.00010 -0.00809" rpy="0 0 0" />
      <mass value="0.00155" />
      <inertia ixx="7.06660E-08" ixy="-6.33539E-12" ixz="-3.03213E-08"
        iyy="1.54849E-07" iyz="3.51578E-13" izz="1.60394E-07" />
    </inertial>
    <visual>
      <origin xyz="0 0 0" rpy="0 0 0" />
      <geometry>
        <mesh filename="meshes/visual/rf_l1.glb" />
      </geometry>
    </visual>
    <collision>
      <origin xyz="0 0 0" rpy="0 0 0" />
      <geometry>
        <mesh filename="meshes/collision/rf_l1.obj" />
      </geometry>
    </collision>
  </link>
  <joint name="R_rf_j1" type="revolute">
    <origin xyz="-0.11324 0.00937 0.00237" rpy="0 0 -0.05660" />
    <parent link="R_hand_base" />
    <child link="R_rf_l1" />
    <axis xyz="0 1 0" />
    <limit lower="-1.0154" upper="0.2840" effort="0.5" velocity="6.28" />
  </joint>
  <link name="R_rf_l2">
    <inertial>
      <origin xyz="-0.01273 0.00009 -0.01968" rpy="0 0 0" />
      <mass value="0.00416" />
      <inertia ixx="4.17200E-07" ixy="-5.15153E-12" ixz="-2.40011E-07"
        iyy="5.74060E-07" iyz="-8.77895E-12" izz="2.32592E-07" />
    </inertial>
    <visual>
      <origin xyz="0 0 0" rpy="0 0 0" />
      <geometry>
        <mesh filename="meshes/visual/rf_l2.glb" />
      </geometry>
    </visual>
    <collision>
      <origin xyz="0 0 0" rpy="0 0 0" />
      <geometry>
        <mesh filename="meshes/collision/rf_l2.obj" />
      </geometry>
    </collision>
  </link>
  <joint name="R_rf_j2" type="revolute">
    <origin xyz="-0.03364 0 -0.01258" rpy="-0.00003 0 0.00010" />
    <parent link="R_rf_l1" />
    <child link="R_rf_l2" />
    <axis xyz="0 1 0" />
    <limit lower="-1.1156" upper="0.3599" effort="0.5" velocity="6.28" />
    <mimic joint="R_rf_j1" multiplier="1.12935" offset="0.00065" />
  </joint>
  <link name="R_lf_l1">
    <inertial>
      <origin xyz="-0.01409 -0.00010 -0.00740" rpy="0 0 0" />
      <mass value="0.00137" />
      <inertia ixx="6.23133E-08" ixy="-5.93152E-13" ixz="-2.07711E-08"
        iyy="1.12814E-07" iyz="1.56840E-13" izz="1.20863E-07" />
    </inertial>
    <visual>
      <origin xyz="0 0 0" rpy="0 0 0" />
      <geometry>
        <mesh filename="meshes/visual/lf_l1.glb" />
      </geometry>
    </visual>
    <collision>
      <origin xyz="0 0 0" rpy="0 0 0" />
      <geometry>
        <mesh filename="meshes/collision/lf_l1.obj" />
      </geometry>
    </collision>
  </link>
  <joint name="R_lf_j1" type="revolute">
    <origin xyz="-0.10947 0.02964 -0.00019" rpy="-0.08722 -0.01033 -0.11755" />
    <parent link="R_hand_base" />
    <child link="R_lf_l1" />
    <axis xyz="0 1 0" />
    <limit lower="-1.0118" upper="0.2811" effort="0.5" velocity="6.28" />
  </joint>
  <link name="R_lf_l2">
    <inertial>
      <origin xyz="-0.00835 0.00012 -0.01408" rpy="0 0 0" />
      <mass value="0.00263" />
      <inertia ixx="1.24022E-07" ixy="6.09239E-10" ixz="-5.50999E-08"
        iyy="1.53209E-07" iyz="1.06950E-09" izz="7.25262E-08" />
    </inertial>
    <visual>
      <origin xyz="0 0 0" rpy="0 0 0" />
      <geometry>
        <mesh filename="meshes/visual/lf_l2.glb" />
      </geometry>
    </visual>
    <collision>
      <origin xyz="0 0 0" rpy="0 0 0" />
      <geometry>
        <mesh filename="meshes/collision/lf_l2.obj" />
      </geometry>
    </collision>
  </link>
  <joint name="R_lf_j2" type="revolute">
    <origin xyz="-0.02974 -0.00005 -0.01163" rpy="-0.00002 0 0" />
    <parent link="R_lf_l1" />
    <child link="R_lf_l2" />
    <axis xyz="0 1 0" />
    <limit lower="-1.1073" upper="0.4014" effort="0.5" velocity="6.28" />
    <mimic joint="R_lf_j1" multiplier="1.15037" offset="0.00186" />
  </joint>

  <!-- finger tip -->
  <link name="R_th_tip" />
  <joint name="R_th_tip_j0" type="fixed">
    <origin xyz="0.0230 -0.0151 -0.0018" rpy="0 0 0" />
    <parent link="R_th_l2" />
    <child link="R_th_tip" />
  </joint>
  <link name="R_ff_tip" />
  <joint name="R_ff_tip_j0" type="fixed">
    <origin xyz="-0.0300 0.0 -0.0400" rpy="0 0 0" />
    <parent link="R_ff_l2" />
    <child link="R_ff_tip" />
  </joint>
  <link name="R_mf_tip" />
  <joint name="R_mf_tip_j0" type="fixed">
    <origin xyz="-0.0304 0.0 -0.0397" rpy="0 0 0" />
    <parent link="R_mf_l2" />
    <child link="R_mf_tip" />
  </joint>
  <link name="R_rf_tip" />
  <joint name="R_rf_tip_j0" type="fixed">
    <origin xyz="-0.0272 0 -0.0420" rpy="0 0 0" />
    <parent link="R_rf_l2" />
    <child link="R_rf_tip" />
  </joint>
  <link name="R_lf_tip" />
  <joint name="R_lf_tip_j0" type="fixed">
    <origin xyz="-0.0182 0 -0.0306" rpy="0 0 0" />
    <parent link="R_lf_l2" />
    <child link="R_lf_tip" />
  </joint>
</robot>